Workbook

Sheet Assessments
A1: 1. Create a new column called Monthly Income.Use a formula to divide Income by 12.
A3: 2. Highlight rows where Income is greater than $80,000.Use a different color to highlight Age under 30 and Purchased Bike = No
A5: 3. Create a bar chart showing average Income by Education level.Add data labels and a title to your chart.
A7: 4. Add a column called High Income. If Income use function to determine the status >70000 put yes and no if less
A9: 5. Add data validation on the payment type and allow users to choose Debit or EFT
A11: 6. Count how many bike buyers are:From Europe AND have 2+ Cars
A13: 7. Create a column called Target Customer:Mark “Yes” if Income > 70,000 AND Age < 40 AND Purchased Bike = No
A15: 8. Create a dashboard that includes:Total # of Bike Purchases ,Purchases by Region (Pie or Bar Chart), Avg. Income of buyers vs non-buyers
A17: 9. Count how many males and females are on the table using the count function
A19: 10. Using INDEX MATCH function find the income of the following ID 15214
A21: 11. Advance Filter for people who: Are under 35, Have Income > 75,000 , Haven’t purchased a bike , Export this list to a new sheet as a sales lead list.
A23: 12. Count the total number of people who purchased a bike.
A25: 13. Using VLOOKUP find the Age for ID 25598

Sheet bike_buyers
A1: ID | B1: Marital Status | C1: Gender | D1: Income | E1: Children | F1: Education | G1: Occupation | H1: Home Owner | I1: Cars | J1: Commute Distance | K1: Region | L1: Age | M1: Purchased Bike | N1: Payment Type | O1: Monthly Income | P1: High Income | Q1: Target Customer | S1: Questions | T1: Answers | V1: Criteria:
A2: 12496 | B2: M | C2: F | D2: 40000 | E2: 1 | F2: Bachelors | G2: Skilled Manual | H2: Yes | I2: 0 | J2: 0-1 Miles | K2: Europe | L2: 42 | M2: No | O2: =D2/12 -> 3333.3333 | P2: =IF(D2>=70000,"Yes",IF(bike_buyers!D2<=70000,"No")) -> No | Q2: =IF(AND(D1>70000, L1<40, M1="No"),"Yes", "") | S2: 6. Bike Buyers From Europe With 2+ Cars | T2: 39 | V2: Age | W2: Income | X2: Purchased Bike
A3: 24107 | B3: M | C3: M | D3: 30000 | E3: 3 | F3: Partial College | G3: Clerical | H3: Yes | I3: 1 | J3: 0-1 Miles | K3: Europe | L3: 43 | M3: No | O3: =D3/12 -> 2500 | P3: =IF(D3>=70000,"Yes",IF(bike_buyers!D3<=70000,"No")) -> No | Q3: =IF(AND(D2>70000, L2<40, M2="No"),"Yes", "") | S3: 9. Count of Males | T3: =COUNTIF(C:C,"M") -> 99 | V3: <35 | W3: >75000 | X3: No
A4: 14177 | B4: M | C4: M | D4: 80000 | E4: 5 | F4: Partial College | G4: Professional | H4: No | I4: 2 | J4: 2-5 Miles | K4: Europe | L4: 60 | M4: No | O4: =D4/12 -> 6666.6667 | P4: =IF(D4>=70000,"Yes",IF(bike_buyers!D4<=70000,"No")) -> Yes | Q4: =IF(AND(D3>70000, L3<40, M3="No"),"Yes", "") | S4: 9. Count of Females | T4: =COUNTIF(C:C,"F") -> 100
A5: 24381 | B5: S | C5: M | D5: 70000 | E5: 0 | F5: Bachelors | G5: Professional | H5: Yes | I5: 1 | J5: 5-10 Miles | K5: Pacific | L5: 41 | M5: Yes | O5: =D5/12 -> 5833.3333 | P5: =IF(D5>=70000,"Yes",IF(bike_buyers!D5<=70000,"No")) -> Yes | Q5: =IF(AND(D4>70000, L4<40, M4="No"),"Yes", "") | S5: 10. Income for ID 15214 | T5: =INDEX(D:D,MATCH(15214,A:A,0)) -> 100000
A6: 25597 | B6: S | C6: M | D6: 30000 | E6: 0 | F6: Bachelors | G6: Clerical | H6: No | I6: 0 | J6: 0-1 Miles | K6: Europe | L6: 36 | M6: Yes | O6: =D6/12 -> 2500 | P6: =IF(D6>=70000,"Yes",IF(bike_buyers!D6<=70000,"No")) -> No | Q6: =IF(AND(D5>70000, L5<40, M5="No"),"Yes", "") | S6: 12. Number of People Who Purchased A Bike | T6: =COUNTIF(M:M, "Yes") -> 105
A7: 13507 | B7: M | C7: F | D7: 10000 | E7: 2 | F7: Partial College | G7: Manual | H7: Yes | I7: 0 | J7: 1-2 Miles | K7: Europe | L7: 50 | M7: No | O7: =D7/12 -> 833.33333 | P7: =IF(D7>=70000,"Yes",IF(bike_buyers!D7<=70000,"No")) -> No | Q7: =IF(AND(D6>70000, L6<40, M6="No"),"Yes", "") | S7: 13. Age For ID 25598 | T7: =VLOOKUP(A22,A:L,12,0) -> 36
A8: 27974 | B8: S | C8: M | D8: 160000 | E8: 2 | F8: High School | G8: Management | H8: Yes | I8: 4 | J8: 0-1 Miles | K8: Pacific | L8: 33 | M8: Yes | O8: =D8/12 -> 13333.333 | P8: =IF(D8>=70000,"Yes",IF(bike_buyers!D8<=70000,"No")) -> Yes | Q8: =IF(AND(D7>70000, L7<40, M7="No"),"Yes", "")
A9: 19364 | B9: M | C9: M | D9: 40000 | E9: 1 | F9: Bachelors | G9: Skilled Manual | H9: Yes | I9: 0 | J9: 0-1 Miles | K9: Europe | L9: 43 | M9: Yes | O9: =D9/12 -> 3333.3333 | P9: =IF(D9>=70000,"Yes",IF(bike_buyers!D9<=70000,"No")) -> No | Q9: =IF(AND(D8>70000, L8<40, M8="No"),"Yes", "")
A10: 22155 | B10: M | C10: M | D10: 20000 | E10: 2 | F10: Partial High School | G10: Clerical | H10: Yes | I10: 2 | J10: 5-10 Miles | K10: Pacific | L10: 58 | M10: No | O10: =D10/12 -> 1666.6667 | P10: =IF(D10>=70000,"Yes",IF(bike_buyers!D10<=70000,"No")) -> No | Q10: =IF(AND(D9>70000, L9<40, M9="No"),"Yes", "")
A11: 19280 | B11: M | C11: M | D11: 120000 | E11: 2 | F11: Partial College | G11: Manual | H11: Yes | I11: 1 | J11: 0-1 Miles | K11: Europe | L11: 40 | M11: Yes | O11: =D11/12 -> 10000 | P11: =IF(D11>=70000,"Yes",IF(bike_buyers!D11<=70000,"No")) -> Yes | Q11: =IF(AND(D10>70000, L10<40, M10="No"),"Yes", "")
A12: 22173 | B12: M | C12: F | D12: 30000 | E12: 3 | F12: High School | G12: Skilled Manual | H12: No | I12: 2 | J12: 1-2 Miles | K12: Pacific | L12: 54 | M12: Yes | O12: =D12/12 -> 2500 | P12: =IF(D12>=70000,"Yes",IF(bike_buyers!D12<=70000,"No")) -> No | Q12: =IF(AND(D11>70000, L11<40, M11="No"),"Yes", "")
A13: 12697 | B13: S | C13: F | D13: 90000 | E13: 0 | F13: Bachelors | G13: Professional | H13: No | I13: 4 | J13: 10+ Miles | K13: Pacific | L13: 36 | M13: No | O13: =D13/12 -> 7500 | P13: =IF(D13>=70000,"Yes",IF(bike_buyers!D13<=70000,"No")) -> Yes | Q13: =IF(AND(D12>70000, L12<40, M12="No"),"Yes", "")
A14: 11434 | B14: M | C14: M | D14: 170000 | E14: 5 | F14: Partial College | G14: Professional | H14: Yes | I14: 0 | J14: 0-1 Miles | K14: Europe | L14: 55 | M14: No | O14: =D14/12 -> 14166.667 | P14: =IF(D14>=70000,"Yes",IF(bike_buyers!D14<=70000,"No")) -> Yes | Q14: =IF(AND(D13>70000, L13<40, M13="No"),"Yes", "") -> Yes
A15: 25323 | B15: M | C15: M | D15: 40000 | E15: 2 | F15: Partial College | G15: Clerical | H15: Yes | I15: 1 | J15: 1-2 Miles | K15: Europe | L15: 35 | M15: Yes | O15: =D15/12 -> 3333.3333 | P15: =IF(D15>=70000,"Yes",IF(bike_buyers!D15<=70000,"No")) -> No | Q15: =IF(AND(D14>70000, L14<40, M14="No"),"Yes", "")
A16: 23542 | B16: S | C16: M | D16: 60000 | E16: 1 | F16: Partial College | G16: Skilled Manual | H16: No | I16: 1 | J16: 0-1 Miles | K16: Pacific | L16: 45 | M16: Yes | O16: =D16/12 -> 5000 | P16: =IF(D16>=70000,"Yes",IF(bike_buyers!D16<=70000,"No")) -> No | Q16: =IF(AND(D15>70000, L15<40, M15="No"),"Yes", "")
A17: 20870 | B17: S | C17: F | D17: 10000 | E17: 2 | F17: High School | G17: Manual | H17: Yes | I17: 1 | J17: 0-1 Miles | K17: Europe | L17: 38 | M17: Yes | O17: =D17/12 -> 833.33333 | P17: =IF(D17>=70000,"Yes",IF(bike_buyers!D17<=70000,"No")) -> No | Q17: =IF(AND(D16>70000, L16<40, M16="No"),"Yes", "")
A18: 23316 | B18: S | C18: M | D18: 30000 | E18: 3 | F18: Partial College | G18: Clerical | H18: No | I18: 2 | J18: 1-2 Miles | K18: Pacific | L18: 59 | M18: Yes | O18: =D18/12 -> 2500 | P18: =IF(D18>=70000,"Yes",IF(bike_buyers!D18<=70000,"No")) -> No | Q18: =IF(AND(D17>70000, L17<40, M17="No"),"Yes", "")
A19: 12610 | B19: M | C19: F | D19: 30000 | E19: 1 | F19: Bachelors | G19: Clerical | H19: Yes | I19: 0 | J19: 0-1 Miles | K19: Europe | L19: 47 | M19: No | O19: =D19/12 -> 2500 | P19: =IF(D19>=70000,"Yes",IF(bike_buyers!D19<=70000,"No")) -> No | Q19: =IF(AND(D18>70000, L18<40, M18="No"),"Yes", "")
... A174: 23963 | B174: M | C174: M | D174: 10000 | E174: 0 | F174: Partial High School | G174: Manual | H174: No | I174: 2 | J174: 0-1 Miles | K174: Europe | L174: 33 | M174: No | O174: =D174/12 -> 833.33333 | P174: =IF(D174>=70000,"Yes",IF(bike_buyers!D174<=70000,"No")) -> No | Q174: =IF(AND(D173>70000, L173<40, M173="No"),"Yes", "")
A175: 17907 | B175: M | C175: F | D175: 10000 | E175: 0 | F175: Partial College | G175: Manual | H175: Yes | I175: 1 | J175: 2-5 Miles | K175: Pacific | L175: 27 | M175: No | O175: =D175/12 -> 833.33333 | P175: =IF(D175>=70000,"Yes",IF(bike_buyers!D175<=70000,"No")) -> No
A176: 19442 | B176: S | C176: M | D176: 50000 | E176: 0 | F176: Graduate Degree | G176: Skilled Manual | H176: Yes | I176: 0 | J176: 0-1 Miles | K176: Europe | L176: 37 | M176: Yes | O176: =D176/12 -> 4166.6667 | P176: =IF(D176>=70000,"Yes",IF(bike_buyers!D176<=70000,"No")) -> No
A177: 17504 | B177: S | C177: F | D177: 80000 | E177: 2 | F177: Partial College | G177: Skilled Manual | H177: Yes | I177: 2 | J177: 5-10 Miles | K177: Pacific | L177: 52 | M177: Yes | O177: =D177/12 -> 6666.6667 | P177: =IF(D177>=70000,"Yes",IF(bike_buyers!D177<=70000,"No")) -> Yes
A178: 12253 | B178: S | C178: F | D178: 20000 | E178: 0 | F178: Partial College | G178: Manual | H178: Yes | I178: 0 | J178: 0-1 Miles | K178: Pacific | L178: 29 | M178: Yes | O178: =D178/12 -> 1666.6667 | P178: =IF(D178>=70000,"Yes",IF(bike_buyers!D178<=70000,"No")) -> No
A179: 27304 | B179: S | C179: F | D179: 110000 | E179: 2 | F179: Partial College | G179: Professional | H179: No | I179: 3 | J179: 5-10 Miles | K179: Europe | L179: 48 | M179: No | O179: =D179/12 -> 9166.6667 | P179: =IF(D179>=70000,"Yes",IF(bike_buyers!D179<=70000,"No")) -> Yes | Q179: =IF(AND(D176>70000, L176<40, M176="No"), "Yes", "")
A180: 14191 | B180: M | C180: M | D180: 160000 | E180: 4 | F180: Partial College | G180: Professional | H180: No | I180: 2 | J180: 10+ Miles | K180: Europe | L180: 55 | M180: Yes | O180: =D180/12 -> 13333.333 | P180: =IF(D180>=70000,"Yes",IF(bike_buyers!D180<=70000,"No")) -> Yes | Q180: =IF(AND(D177>70000, L177<40, M177="No"), "Yes", "")
A181: 12212 | B181: M | C181: F | D181: 10000 | E181: 0 | F181: Graduate Degree | G181: Manual | H181: Yes | I181: 0 | J181: 0-1 Miles | K181: Europe | L181: 37 | M181: Yes | O181: =D181/12 -> 833.33333 | P181: =IF(D181>=70000,"Yes",IF(bike_buyers!D181<=70000,"No")) -> No
A182: 25529 | B182: S | C182: M | D182: 10000 | E182: 1 | F182: Graduate Degree | G182: Manual | H182: Yes | I182: 0 | J182: 0-1 Miles | K182: Europe | L182: 44 | M182: No | O182: =D182/12 -> 833.33333 | P182: =IF(D182>=70000,"Yes",IF(bike_buyers!D182<=70000,"No")) -> No
A183: 22170 | B183: M | C183: F | D183: 30000 | E183: 3 | F183: Partial College | G183: Clerical | H183: No | I183: 2 | J183: 1-2 Miles | K183: Pacific | L183: 55 | M183: Yes | O183: =D183/12 -> 2500 | P183: =IF(D183>=70000,"Yes",IF(bike_buyers!D183<=70000,"No")) -> No
A184: 19445 | B184: M | C184: F | D184: 10000 | E184: 2 | F184: High School | G184: Manual | H184: No | I184: 1 | J184: 0-1 Miles | K184: Europe | L184: 38 | M184: No | O184: =D184/12 -> 833.33333 | P184: =IF(D184>=70000,"Yes",IF(bike_buyers!D184<=70000,"No")) -> No
A185: 15265 | B185: S | C185: M | D185: 40000 | E185: 2 | F185: Bachelors | G185: Management | H185: Yes | I185: 2 | J185: 5-10 Miles | K185: Pacific | L185: 66 | M185: Yes | O185: =D185/12 -> 3333.3333 | P185: =IF(D185>=70000,"Yes",IF(bike_buyers!D185<=70000,"No")) -> No
A186: 28918 | B186: M | C186: F | D186: 130000 | E186: 4 | F186: High School | G186: Management | H186: No | I186: 4 | J186: 10+ Miles | K186: Europe | L186: 58 | M186: No | O186: =D186/12 -> 10833.333 | P186: =IF(D186>=70000,"Yes",IF(bike_buyers!D186<=70000,"No")) -> Yes | Q186: =IF(AND(D183>70000, L183<40, M183="No"), "Yes", "")
A187: 15799 | B187: M | C187: F | D187: 90000 | E187: 1 | F187: Bachelors | G187: Professional | H187: Yes | I187: 1 | J187: 2-5 Miles | K187: Pacific | L187: 47 | M187: Yes | O187: =D187/12 -> 7500 | P187: =IF(D187>=70000,"Yes",IF(bike_buyers!D187<=70000,"No")) -> Yes
A188: 11047 | B188: M | C188: F | D188: 30000 | E188: 3 | F188: High School | G188: Skilled Manual | H188: No | I188: 2 | J188: 1-2 Miles | K188: Pacific | L188: 56 | M188: Yes | O188: =D188/12 -> 2500 | P188: =IF(D188>=70000,"Yes",IF(bike_buyers!D188<=70000,"No")) -> No
A189: 18151 | B189: S | C189: M | D189: 80000 | E189: 5 | F189: Partial College | G189: Professional | H189: No | I189: 2 | J189: 10+ Miles | K189: Europe | L189: 59 | M189: No | O189: =D189/12 -> 6666.6667 | P189: =IF(D189>=70000,"Yes",IF(bike_buyers!D189<=70000,"No")) -> Yes | Q189: =IF(AND(D186>70000, L186<40, M186="No"), "Yes", "")
A190: 20606 | B190: M | C190: F | D190: 70000 | E190: 0 | F190: Bachelors | G190: Professional | H190: Yes | I190: 4 | J190: 10+ Miles | K190: Pacific | L190: 32 | M190: Yes | O190: =D190/12 -> 5833.3333 | P190: =IF(D190>=70000,"Yes",IF(bike_buyers!D190<=70000,"No")) -> Yes
A191: 19482 | B191: M | C191: M | D191: 30000 | E191: 1 | F191: Partial College | G191: Clerical | H191: Yes | I191: 1 | J191: 0-1 Miles | K191: Europe | L191: 44 | M191: Yes | O191: =D191/12 -> 2500 | P191: =IF(D191>=70000,"Yes",IF(bike_buyers!D191<=70000,"No")) -> No
A192: 16489 | B192: M | C192: M | D192: 30000 | E192: 3 | F192: High School | G192: Skilled Manual | H192: Yes | I192: 2 | J192: 5-10 Miles | K192: Pacific | L192: 55 | M192: No | O192: =D192/12 -> 2500 | P192: =IF(D192>=70000,"Yes",IF(bike_buyers!D192<=70000,"No")) -> No
A193: 26944 | B193: S | C193: M | D193: 90000 | E193: 2 | F193: High School | G193: Manual | H193: Yes | I193: 0 | J193: 0-1 Miles | K193: Europe | L193: 36 | M193: Yes | O193: =D193/12 -> 7500 | P193: =IF(D193>=70000,"Yes",IF(bike_buyers!D193<=70000,"No")) -> Yes
A194: 15682 | B194: S | C194: F | D194: 80000 | E194: 5 | F194: Bachelors | G194: Management | H194: Yes | I194: 2 | J194: 10+ Miles | K194: Europe | L194: 62 | M194: No | O194: =D194/12 -> 6666.6667 | P194: =IF(D194>=70000,"Yes",IF(bike_buyers!D194<=70000,"No")) -> Yes | Q194: =IF(AND(D191>70000, L191<40, M191="No"), "Yes", "")
...

Sheet Dashboard
A1: Row Labels | B1: Average of Income
A2: Bachelors | B2: 53492.063 | F2: Total Bike Purchases:
A3: High School | B3: 50526.316 | F3: 105
A4: Partial College | B4: 49558.824
A5: Graduate Degree | B5: 46666.667
A6: Partial High School | B6: 21333.333
A7: Grand Total | B7: 48643.216
A9: Row Labels | B9: Count of Purchased Bike
A10: Europe | B10: 123
A11: Pacific | B11: 76
A12: Grand Total | B12: 199
A14: Row Labels | B14: Average of Income
A15: Yes | B15: 48285.714
A16: No | B16: 49042.553
A17: Grand Total | B17: 48643.216

Sheet Sales Leads
A1: ID | B1: Marital Status | C1: Gender | D1: Income | E1: Children | F1: Education | G1: Occupation | H1: Home Owner | I1: Cars | J1: Commute Distance | K1: Region | L1: Age | M1: Purchased Bike | N1: Payment Type | O1: Monthly Income | P1: High Income | Q1: Target Customer
A2: 12678 | B2: S | C2: F | D2: 130000 | E2: 4 | F2: High School | G2: Management | H2: Yes | I2: 4 | J2: 0-1 Miles | K2: Pacific | L2: 31 | M2: No | O2: 10833.333 | P2: Yes
A3: 12344 | B3: S | C3: F | D3: 80000 | E3: 0 | F3: Bachelors | G3: Professional | H3: No | I3: 3 | J3: 10+ Miles | K3: Pacific | L3: 31 | M3: No | O3: 6666.6667 | P3: Yes
A4: 16614 | B4: M | C4: F | D4: 80000 | E4: 0 | F4: Bachelors | G4: Professional | H4: Yes | I4: 3 | J4: 10+ Miles | K4: Pacific | L4: 32 | M4: No | O4: 6666.6667 | P4: Yes
